An exception occurred! => 500 
{'traceback': {'tb_frame': {'f_code': {'co_name': 'post', 'co_filename': '/flyt/flytos/flytcore/lib/python2.7/dist-packages/rostful/flask_views.py'}, 'f_globals': {'__name__': 'rostful.flask_views', '__file__': '/flyt/flytos/flytcore/lib/python2.7/dist-packages/rostful/flask_views.pyc'}}, 'tb_next': {'tb_frame': {'f_code': {'co_name': 'service_call', 'co_filename': '/flyt/flytos/flytcore/lib/python2.7/dist-packages/pyros/pyros_client.py'}, 'f_globals': {'__name__': 'pyros.pyros_client', '__file__': '/flyt/flytos/flytcore/lib/python2.7/dist-packages/pyros/pyros_client.pyc'}}, 'tb_next': {'tb_frame': {'f_code': {'co_name': 'call', 'co_filename': '/usr/local/lib/python2.7/dist-packages/pyzmp/service.py'}, 'f_globals': {'__name__': 'pyzmp.service', '__file__': '/usr/local/lib/python2.7/dist-packages/pyzmp/service.pyc'}}, 'tb_next': {'tb_frame': {'f_code': {'co_name': 'run', 'co_filename': '/usr/local/lib/python2.7/dist-packages/pyzmp/node.py'}, 'f_globals': {'__name__': 'pyzmp.node', '__file__': '/usr/local/lib/python2.7/dist-packages/pyzmp/node.pyc'}}, 'tb_next': {'tb_frame': {'f_code': {'co_name': 'service', 'co_filename': '/flyt/flytos/flytcore/lib/python2.7/dist-packages/pyros/pyros_ros.py'}, 'f_globals': {'__name__': 'pyros.pyros_ros', '__file__': '/flyt/flytos/flytcore/lib/python2.7/dist-packages/pyros/pyros_ros.pyc'}}, 'tb_next': {'tb_frame': {'f_code': {'co_name': 'call', 'co_filename': '/flyt/flytos/flytcore/lib/python2.7/dist-packages/pyros/rosinterface/service.py'}, 'f_globals': {'__name__': 'pyros.rosinterface.service', '__file__': '/flyt/flytos/flytcore/lib/python2.7/dist-packages/pyros/rosinterface/service.pyc'}}, 'tb_next': {'tb_frame': {'f_code': {'co_name': '__call__', 'co_filename': '/opt/ros/kinetic/lib/python2.7/dist-packages/rospy/impl/tcpros_service.py'}, 'f_globals': {'__name__': 'rospy.impl.tcpros_service', '__file__': '/opt/ros/kinetic/lib/python2.7/dist-packages/rospy/impl/tcpros_service.pyc'}}, 'tb_next': {'tb_frame': {'f_code': {'co_name': 'call', 'co_filename': '/opt/ros/kinetic/lib/python2.7/dist-packages/rospy/impl/tcpros_service.py'}, 'f_globals': {'__name__': 'rospy.impl.tcpros_service', '__file__': '/opt/ros/kinetic/lib/python2.7/dist-packages/rospy/impl/tcpros_service.pyc'}}, 'tb_next': None, 'tb_lineno': 505}, 'tb_lineno': 435}, 'tb_lineno': 92}, 'tb_lineno': 118}, 'tb_lineno': 419}, 'tb_lineno': 142}, 'tb_lineno': 162}, 'tb_lineno': 500}, 'exc_type': "<class 'rospy.service.ServiceException'>", 'exc_value': 'unable to connect to service: [Errno 111] Connection refused'}
An exception occurred! => 500 
{'traceback': {'tb_frame': {'f_code': {'co_name': 'post', 'co_filename': '/flyt/flytos/flytcore/lib/python2.7/dist-packages/rostful/flask_views.py'}, 'f_globals': {'__name__': 'rostful.flask_views', '__file__': '/flyt/flytos/flytcore/lib/python2.7/dist-packages/rostful/flask_views.pyc'}}, 'tb_next': {'tb_frame': {'f_code': {'co_name': 'service_call', 'co_filename': '/flyt/flytos/flytcore/lib/python2.7/dist-packages/pyros/pyros_client.py'}, 'f_globals': {'__name__': 'pyros.pyros_client', '__file__': '/flyt/flytos/flytcore/lib/python2.7/dist-packages/pyros/pyros_client.pyc'}}, 'tb_next': {'tb_frame': {'f_code': {'co_name': 'call', 'co_filename': '/usr/local/lib/python2.7/dist-packages/pyzmp/service.py'}, 'f_globals': {'__name__': 'pyzmp.service', '__file__': '/usr/local/lib/python2.7/dist-packages/pyzmp/service.pyc'}}, 'tb_next': {'tb_frame': {'f_code': {'co_name': 'run', 'co_filename': '/usr/local/lib/python2.7/dist-packages/pyzmp/node.py'}, 'f_globals': {'__name__': 'pyzmp.node', '__file__': '/usr/local/lib/python2.7/dist-packages/pyzmp/node.pyc'}}, 'tb_next': {'tb_frame': {'f_code': {'co_name': 'service', 'co_filename': '/flyt/flytos/flytcore/lib/python2.7/dist-packages/pyros/pyros_ros.py'}, 'f_globals': {'__name__': 'pyros.pyros_ros', '__file__': '/flyt/flytos/flytcore/lib/python2.7/dist-packages/pyros/pyros_ros.pyc'}}, 'tb_next': {'tb_frame': {'f_code': {'co_name': 'call', 'co_filename': '/flyt/flytos/flytcore/lib/python2.7/dist-packages/pyros/rosinterface/service.py'}, 'f_globals': {'__name__': 'pyros.rosinterface.service', '__file__': '/flyt/flytos/flytcore/lib/python2.7/dist-packages/pyros/rosinterface/service.pyc'}}, 'tb_next': {'tb_frame': {'f_code': {'co_name': '__call__', 'co_filename': '/opt/ros/kinetic/lib/python2.7/dist-packages/rospy/impl/tcpros_service.py'}, 'f_globals': {'__name__': 'rospy.impl.tcpros_service', '__file__': '/opt/ros/kinetic/lib/python2.7/dist-packages/rospy/impl/tcpros_service.pyc'}}, 'tb_next': {'tb_frame': {'f_code': {'co_name': 'call', 'co_filename': '/opt/ros/kinetic/lib/python2.7/dist-packages/rospy/impl/tcpros_service.py'}, 'f_globals': {'__name__': 'rospy.impl.tcpros_service', '__file__': '/opt/ros/kinetic/lib/python2.7/dist-packages/rospy/impl/tcpros_service.pyc'}}, 'tb_next': None, 'tb_lineno': 505}, 'tb_lineno': 435}, 'tb_lineno': 92}, 'tb_lineno': 118}, 'tb_lineno': 419}, 'tb_lineno': 142}, 'tb_lineno': 162}, 'tb_lineno': 500}, 'exc_type': "<class 'rospy.service.ServiceException'>", 'exc_value': 'unable to connect to service: [Errno 111] Connection refused'}
An exception occurred! => 500 
{'traceback': {'tb_frame': {'f_code': {'co_name': 'post', 'co_filename': '/flyt/flytos/flytcore/lib/python2.7/dist-packages/rostful/flask_views.py'}, 'f_globals': {'__name__': 'rostful.flask_views', '__file__': '/flyt/flytos/flytcore/lib/python2.7/dist-packages/rostful/flask_views.pyc'}}, 'tb_next': {'tb_frame': {'f_code': {'co_name': 'service_call', 'co_filename': '/flyt/flytos/flytcore/lib/python2.7/dist-packages/pyros/pyros_client.py'}, 'f_globals': {'__name__': 'pyros.pyros_client', '__file__': '/flyt/flytos/flytcore/lib/python2.7/dist-packages/pyros/pyros_client.pyc'}}, 'tb_next': {'tb_frame': {'f_code': {'co_name': 'call', 'co_filename': '/usr/local/lib/python2.7/dist-packages/pyzmp/service.py'}, 'f_globals': {'__name__': 'pyzmp.service', '__file__': '/usr/local/lib/python2.7/dist-packages/pyzmp/service.pyc'}}, 'tb_next': {'tb_frame': {'f_code': {'co_name': 'run', 'co_filename': '/usr/local/lib/python2.7/dist-packages/pyzmp/node.py'}, 'f_globals': {'__name__': 'pyzmp.node', '__file__': '/usr/local/lib/python2.7/dist-packages/pyzmp/node.pyc'}}, 'tb_next': {'tb_frame': {'f_code': {'co_name': 'service', 'co_filename': '/flyt/flytos/flytcore/lib/python2.7/dist-packages/pyros/pyros_ros.py'}, 'f_globals': {'__name__': 'pyros.pyros_ros', '__file__': '/flyt/flytos/flytcore/lib/python2.7/dist-packages/pyros/pyros_ros.pyc'}}, 'tb_next': {'tb_frame': {'f_code': {'co_name': 'call', 'co_filename': '/flyt/flytos/flytcore/lib/python2.7/dist-packages/pyros/rosinterface/service.py'}, 'f_globals': {'__name__': 'pyros.rosinterface.service', '__file__': '/flyt/flytos/flytcore/lib/python2.7/dist-packages/pyros/rosinterface/service.pyc'}}, 'tb_next': {'tb_frame': {'f_code': {'co_name': '__call__', 'co_filename': '/opt/ros/kinetic/lib/python2.7/dist-packages/rospy/impl/tcpros_service.py'}, 'f_globals': {'__name__': 'rospy.impl.tcpros_service', '__file__': '/opt/ros/kinetic/lib/python2.7/dist-packages/rospy/impl/tcpros_service.pyc'}}, 'tb_next': {'tb_frame': {'f_code': {'co_name': 'call', 'co_filename': '/opt/ros/kinetic/lib/python2.7/dist-packages/rospy/impl/tcpros_service.py'}, 'f_globals': {'__name__': 'rospy.impl.tcpros_service', '__file__': '/opt/ros/kinetic/lib/python2.7/dist-packages/rospy/impl/tcpros_service.pyc'}}, 'tb_next': None, 'tb_lineno': 505}, 'tb_lineno': 435}, 'tb_lineno': 92}, 'tb_lineno': 118}, 'tb_lineno': 419}, 'tb_lineno': 142}, 'tb_lineno': 162}, 'tb_lineno': 500}, 'exc_type': "<class 'rospy.service.ServiceException'>", 'exc_value': 'unable to connect to service: [Errno 111] Connection refused'}
Starting Tornado server on 0.0.0.0:80
Starting Tornado server on 0.0.0.0:80
Starting Tornado server on 0.0.0.0:80
Starting Tornado server on 0.0.0.0:80
Starting Tornado server on 0.0.0.0:80
Starting Tornado server on 0.0.0.0:80
Starting Tornado server on 0.0.0.0:80
Starting Tornado server on 0.0.0.0:80
Starting Tornado server on 0.0.0.0:80
Starting Tornado server on 0.0.0.0:80
Starting Tornado server on 0.0.0.0:80
Starting Tornado server on 0.0.0.0:80
Starting Tornado server on 0.0.0.0:80
Starting Tornado server on 0.0.0.0:80
Starting Tornado server on 0.0.0.0:80
Starting Tornado server on 0.0.0.0:80
Starting Tornado server on 0.0.0.0:80
Starting Tornado server on 0.0.0.0:80
Starting Tornado server on 0.0.0.0:80
Starting Tornado server on 0.0.0.0:80
Starting Tornado server on 0.0.0.0:80
Starting Tornado server on 0.0.0.0:80
Starting Tornado server on 0.0.0.0:80
Starting Tornado server on 0.0.0.0:80
Starting Tornado server on 0.0.0.0:80
Starting Tornado server on 0.0.0.0:80
Starting Tornado server on 0.0.0.0:80
Starting Tornado server on 0.0.0.0:80
Starting Tornado server on 0.0.0.0:80
Starting Tornado server on 0.0.0.0:80
Starting Tornado server on 0.0.0.0:80
